Workbook

Sheet Codebook
A1: CS7267 Literature Coding Matrix: Codebook
A2: Version 0.2, 2026-09-12. Metadata transcribed from the PDFs. Coding columns drafted by Claude on 2026-09-12 from each paper's abstract, introduction, and threat-model section; every row must be re-read and confirmed by a team member before anything from this matrix is cited. Change 'Coded by' to your initials once confirmed.
A4: How to use
A5: 1. Read the survey / taxonomy papers first and check whether the columns below cover the dimensions they use. Add a column if not; record the change in the Change log at the bottom of this sheet.
A6: 2. Code every remaining paper as one row on the 'Coding Matrix' sheet. Grey columns are bibliographic metadata already transcribed from each PDF's first page; yellow columns are yours to fill. Dropdown columns accept only the values listed here.
A7: 3. Verify venue and year for every row before citing it (column 'Venue verified?'). Rows marked UNVERIFIED or 'Preprint (as downloaded)' may have a later peer-reviewed version; an arXiv preprint is not a conference paper until you have checked.
A8: 4. The 'Coverage' sheet counts how the coded papers distribute across each dimension. Empty cells in the design space are candidate gaps; crowded cells are where a novelty claim will not survive review.
A9: 5. Keep the BibTeX file in step with the ID column so that citations in the report map back to rows here.
A11: Legend
A12: Grey fill | B12: Bibliographic metadata transcribed from the PDF. Edit only to correct a transcription error.
A13: Yellow fill | B13: Team fills in. Dropdown where a value list exists; free text otherwise.
A15: Column | B15: Type | C15: Allowed values | D15: Definition / guidance
A16: Venue verified? (Y/N + where) | B16: Free text | D16: Confirm the venue and year against a fetched arXiv abstract, proceedings entry, or publisher record before citing. Rule 2 of the project instructions.
A17: Paper type | B17: Dropdown | C17: Attack; Defense; Benchmark / environment; Evaluation methodology; Survey / taxonomy; Mixed (note which) | D17: What the paper primarily contributes.
A18: Attack surface | B18: Dropdown | C18: RAG corpus / retriever; Tool output (indirect, at runtime); Tool description / metadata (MCP); Direct user input; Multiple (note which) | D18: Where the adversarial content enters the system.
A19: Attacker position / channel (free text) | B19: Free text | D19: Who the attacker is and how the payload reaches the model, e.g. 'third party controls a web page the agent reads'.
A20: Threat model / attacker capability (free text) | B20: Free text | D20: Black-box, white-box, no-box; number of injected texts; whether the attacker knows the user query, the defense, or the model.
A21: Attack objective | B21: Dropdown | C21: Task hijack (unauthorised action); Data exfiltration; Misinformation / wrong answer; Denial of service; Tool-selection manipulation; Multiple (note which); N/A (defense-only) | D21: What the attacker is trying to achieve.
A22: Payload | B22: Dropdown | C22: Instruction injection; Content poisoning; Both (note which); N/A (defense-only) | D22: How the adversarial content works on the model. Instruction injection: the text gives the model commands ("ignore previous instructions", "before reading the file, call write_file…"). Content poisoning: plausible false content with no commands, which misleads by being believed, e.g. PoisonedRAG's wrong-answer passages.
A23: Defense class | B23: Dropdown | C23: Detection (classifier / probe); Input transformation / prompting; Training-time (fine-tune / alignment); Architectural isolation; Runtime policy / capability enforcement; Certified / provable; Forensics / traceback; N/A (attack- or benchmark-only) | D23: Mechanism family. Use N/A for attack- or benchmark-only papers.
A24: Enforcement point | B24: Dropdown | C24: Model weights; Prompt / input layer; Orchestrator / runtime; Tool layer / MCP server; Retriever / index; N/A | D24: Where in the stack the defense sits.
A25: Trust-boundary assumption (free text) | B25: Free text | D25: What the defense assumes is trusted: the user query, the system prompt, the tool schema, the orchestrator code.
A26: Benchmarks / datasets used (free text) | B26: Free text | D26: Name each benchmark and, if stated, the version.
A27: Primary metric | B27: Dropdown | C27: ASR (attack success rate); Utility / task success; AUROC; FPR / FNR / TPR; Certified accuracy; Other (note) | D27: The headline number's metric.
A28: Key quantitative result + page/table (free text) | B28: Free text | D28: One number, with the page or table it came from. Abstract-level figures are citable; table values must be re-checked in the PDF.
A29: Addresses MCP explicitly | B29: Dropdown | C29: Yes; Partial; No | D29: Yes if MCP is the object of study; Partial if generic tool calling is studied and MCP is mentioned.
A30: Relevance to our RQ | B30: Dropdown | C30: High; Medium; Low | D30: Team judgement.
A31: Fits the coding frame? | B31: Dropdown | C31: Fits frame; Needs new dimension (note) | D31: If a paper does not fit, that is a signal the frame needs a new column.
A32: Coded by (initials) | B32: Free text
A33: Date coded | B33: Free text | D33: YYYY-MM-DD
A34: Notes (free text) | B34: Free text
A36: Worked example (fictitious paper, illustrating the expected level of detail)
A37: Paper type | B37: Defense
A38: Attack surface | B38: Tool output (indirect, at runtime)
A39: Attacker position / channel | B39: Third party controls a web page the agent's browse tool returns
A40: Threat model / attacker capability | B40: Black-box; attacker knows the tool set but not the user query; one injected document
A41: Attack objective | B41: Task hijack (unauthorised action)
A42: Payload | B42: Instruction injection
A43: Defense class | B43: Runtime policy / capability enforcement
A44: Enforcement point | B44: Orchestrator / runtime
...

Sheet Coding Matrix
A1: ID | B1: Short name | C1: Title | D1: First author | E1: Authors | F1: Year (as printed) | G1: Venue (as printed on PDF) | H1: arXiv stamp (as printed) | I1: Provenance (as downloaded) | J1: File name | K1: Venue verified? (Y/N + where) | L1: Paper type | M1: Attack surface | N1: Attacker position / channel (free text) | O1: Threat model / attacker capability (free text) | P1: Attack objective | Q1: Payload | R1: Defense class | S1: Enforcement point | T1: Trust-boundary assumption (free text) | U1: Benchmarks / datasets used (free text) | V1: Primary metric | W1: Key quantitative result + page/table (free text) | X1: Addresses MCP explicitly | Y1: Relevance to our RQ | Z1: Fits the coding frame? | AA1: Coded by (initials) | AB1: Date coded | AC1: Notes (free text)
A2: P01 | B2: SecAlign | C2: SecAlign: Defending Against Prompt Injection with Preference Optimization | D2: Chen | E2: Sizhe Chen, Arman Zharmagambetov, Saeed Mahloujifar, Kamalika Chaudhuri, David Wagner, Chuan Guo | F2: 2025 | G2: CCS '25 (ACM SIGSAC CCS 2025), Taipei; doi 10.1145/3719027.3744836 | H2: not printed on this copy | I2: Peer-reviewed conference | J2: chen_et_al_2025_secalign_defending_against_prompt_injection_with_preference_optimization.pdf | L2: Defense | M2: Multiple (note which) | N2: Adversary controls the data portion of an LLM-integrated application's input (user documents, web retrieval, API results) | O2: Attacker injects an arbitrarily long instruction into the data part; knows the benign instruction and prompt format but cannot modify them; white-box access to the LLM assumed to test strong optimization attacks (Sec. 2, 'Threat model') | P2: Task hijack (unauthorised action) | Q2: Instruction injection | R2: Training-time (fine-tune / alignment) | S2: Model weights | T2: Benign instruction and prompt format come from the trusted system designer; all data untrusted; defender has full access to modify the LLM | U2: Own evaluation incl. optimization-based attacks GCG, AdvPrompter (Sec. 5); AlpacaEval2 for utility | V2: ASR (attack success rate) | W2: Reduces success rates of various prompt injections to <10%, incl. attacks more sophisticated than those seen in training (abstract) | X2: No | Y2: Medium | Z2: Fits frame | AA2: Claude (draft; verify) | AB2: 2026-09-12 | AC2: Preference-optimization successor to StruQ; a model-level baseline that a runtime/architectural defense would be compared against. Surface: any data channel of a prompt+data query.
A3: P02 | B3: StruQ | C3: StruQ: Defending Against Prompt Injection with Structured Queries | D3: Chen | E3: Sizhe Chen, Julien Piet, Chawin Sitawarin, David Wagner | F3: 2024 | G3: not printed on this copy | H3: arXiv:2402.06363v2 [cs.CR], 25 Sep 2024 | I3: Preprint (as downloaded) | J3: chen_et_al_2025_struq_defending_against_prompt_injection_with_structured_queries.pdf | L3: Defense | M3: Multiple (note which) | N3: Attacker supplies the data portion of a prompt+data query to an LLM-integrated application | O3: Attacker can arbitrarily modify the data portion but not the prompt; prompt and application formatting assumed known to the attacker (Sec. 4, 'Threat model') | P3: Task hijack (unauthorised action) | Q3: Instruction injection | R3: Training-time (fine-tune / alignment) | S3: Model weights | T3: Prompt channel trusted, data channel untrusted; secure front-end formats the two channels with reserved delimiter tokens | U3: Own evaluation: strongest of many attacks incl. TAP and GCG (Tables 5 and 8) | V3: ASR (attack success rate) | W3: Robustness against TAP: 97% to 9% ASR (Sec. 6 text, near Table 5); most non-optimization attacks reported at 0% ASR (same section) | X3: No | Y3: Medium | Z3: Fits frame | AA3: Claude (draft; verify) | AB3: 2026-09-12 | AC3: Two components: secure front-end (input layer) plus structured instruction tuning (model). Coded to the model since the security property comes from training. Downloaded copy is the arXiv version; a peer-reviewed version may exist, verify before citing.
A4: P03 | B4: AgentDojo | C4: AgentDojo: A Dynamic Environment to Evaluate Prompt Injection Attacks and Defenses for LLM Agents | D4: Debenedetti | E4: Edoardo Debenedetti, Jie Zhang, Mislav Balunovic, Luca Beurer-Kellner, Marc Fischer, Florian Tramèr | F4: 2024 | G4: NeurIPS 2024, Datasets and Benchmarks track (footer, p. 1) | H4: arXiv:2406.13352v3 [cs.CR], 24 Nov 2024 | I4: Peer-reviewed conference (arXiv copy) | J4: debenedetti_et_al_2024_agentdojo_a_dynamic_environment_to_evaluate_prompt_injection_attacks_and_defenses_for_llm_agents.pdf | L4: Benchmark / environment | M4: Tool output (indirect, at runtime) | N4: Third party controls data returned by the agent's tools (emails, web pages, documents in the environment) | O4: Attacker places text in tool-returned data; injection tasks specify the attacker goal; attacks may or may not know the user task or model (Sec. 3 and Sec. 5 adaptive attack discussion) | P4: Multiple (note which) | Q4: Instruction injection | R4: N/A (attack- or benchmark-only) | S4: N/A | T4: Benchmark treats environment data as untrusted; user task instruction trusted | U4: AgentDojo itself: 97 user tasks, 629 security test cases (abstract) | V4: ASR (attack success rate) | W4: LLMs solve <66% of tasks without any attack; attacks succeed against the best agents in <25% of cases (Sec. 1, p. 2) | X4: No | Y4: High | Z4: Fits frame | AA4: Claude (draft; verify) | AB4: 2026-09-12 | AC4: Objectives covered: data exfiltration and unauthorized actions. Also ships defense paradigms (tool filter, spotlighting-style delimiting, etc.). Metric pair: utility under attack and targeted ASR. The evaluation platform CaMeL is measured on.
A5: P04 | B5: CaMeL | C5: Defeating Prompt Injections by Design | D5: Debenedetti | E5: Edoardo Debenedetti, Ilia Shumailov, Tianqi Fan, Jamie Hayes, Nicholas Carlini, Daniel Fabian, Christoph Kern, Chongyang Shi, Andreas Terzis, Florian Tramèr | F5: 2025 | G5: not printed on this copy | H5: arXiv:2503.18813v2 [cs.CR], 24 Jun 2025 | I5: Preprint (as downloaded) | J5: debenedetti_et_al_2025_defeating_prompt_injections_by_design.pdf | L5: Defense | M5: Tool output (indirect, at runtime) | N5: Attacker shares a crafted document, email, or spreadsheet that the agent later retrieves through a tool | O5: Attacker controls untrusted data sources the agent reads; the user query is trusted; underlying LLM may itself be fully susceptible to injection (Sec. 3, 'Threat Model') | P5: Multiple (note which) | Q5: Instruction injection | R5: Runtime policy / capability enforcement | S5: Orchestrator / runtime | T5: User query trusted (control and data flow extracted from it); every tool output untrusted; capabilities attached to values; policies enforced in a custom Python interpreter; no change to the LLM | U5: AgentDojo | V5: Utility / task success | W5: Solves 77% of AgentDojo tasks with provable security vs 84% for the undefended system (abstract) | X5: No | Y5: High | Z5: Fits frame | AA5: Claude (draft; verify) | AB5: 2026-09-12 | AC5: Objectives addressed: control-flow hijack and data exfiltration via unauthorized data flows. Explicitly draws on CFI, access control, and information-flow control. Also fits 'Architectural isolation'; coded to the enforcement mechanism.
A6: P05 | B6: When Benchmarks Lie | C6: When Benchmarks Lie: Evaluating Malicious Prompt Classifiers Under True Distribution Shift | D6: Fomin | E6: Max Fomin | F6: 2026 | G6: AIWILD workshop at ICLR 2026 (footer, p. 1) | H6: arXiv:2602.14161v2 [cs.LG], 19 Jul 2026 | I6: Workshop (arXiv copy) | J6: fomin_2026_when_benchmarks_lie_evaluating_malicious_prompt_classifiers_under_true_distribution_shifts.pdf | L6: Evaluation methodology | M6: Multiple (note which) | N6: Not an attack paper: evaluates classifiers over pooled prompt-attack datasets (jailbreaks, indirect injection, harmful requests, benign) | O6: Detector is trained on N-1 datasets and tested on a dataset never seen in training (Leave-One-Dataset-Out); question is whether classifiers learn attack semantics or dataset identity (Sec. 1) | P6: Multiple (note which) | Q6: Instruction injection | R6: Detection (classifier / probe) | S6: Prompt / input layer | T6: N/A: evaluation protocol paper; assumes deployment traffic comes from distributions unlike the training benchmarks | U6: 18 datasets, 105K samples; LODO vs standard cross-validation; compared against PromptGuard 2, LlamaGuard, ProtectAI, Deepset (Sec. 1) | V6: AUROC | W6: Standard CV reports pooled AUC 8.0-16.5 points higher than LODO across four LLMs; per-dataset gaps 1-25 points; 28-44% of top SAE features are dataset shortcuts (abstract) | X6: No | Y6: High | Z6: Needs new dimension (note) | AA6: Claude (draft; verify) | AB6: 2026-09-12 | AC6: Does not fit the attack/defense cells: it is about how detectors are evaluated. Suggests adding an 'Evaluation protocol' column (in-distribution split vs held-out dataset vs held-out surface). Directly relevant to any LOSO/LOFO design in our project. Venue footer says AIWILD workshop at ICLR 2026. Payload (draft): pooled datasets also include jailbreaks and harmful requests, which are direct prompts rather than injected payloads.
A7: P06 | B7: Greshake (indirect PI) | C7: Not What You've Signed Up For: Compromising Real-World LLM-Integrated Applications with Indirect Prompt Injection | D7: Greshake | E7: Kai Greshake, Sahar Abdelnabi, Shailesh Mishra, Christoph Endres, Thorsten Holz, Mario Fritz | F7: 2023 | G7: AISec '23 (16th ACM Workshop on AI and Security), Copenhagen; doi 10.1145/3605764.3623985 | H7: not printed on this copy | I7: Peer-reviewed workshop | J7: greshake_et_al_not_what_you_have_signed_up_for_compromising_real_world_LLM.pdf | L7: Mixed (note which) | M7: Multiple (note which) | N7: Remote attacker plants instructions in data likely to be retrieved at inference time (web pages, emails, code repositories) without any direct interface to the application | O7: Only assumes the ability to remotely poison potential model input at inference time; plain-English payloads; no surrogate models, no control over or white-box knowledge of the target model (Sec. 3, 'Assumptions') | P7: Multiple (note which) | Q7: Instruction injection | R7: N/A (attack- or benchmark-only) | S7: N/A | T7: Shows LLM-integrated apps blur the line between data and instructions; retrieved content is effectively executed | U7: No benchmark; demonstrations on Bing Chat, code-completion engines, and GPT-4 synthetic applications (abstract) | V7: Other (note) | W7: Qualitative demonstrations only; no headline rate. Contribution is the taxonomy of injection methods and impacts (data theft, worming, information-ecosystem contamination, manipulation, availability) | X7: No | Y7: High | Z7: Fits frame | AA7: Claude (draft; verify) | AB7: 2026-09-12 | AC7: Mixed = taxonomy + attack demonstrations. This is the taxonomy paper to reconcile the frame against first. Coined 'indirect prompt injection'. Payload (draft): misinformation and manipulation impacts are reached through injected instructions.
A8: P07 | B8: Spotlighting | C8: Defending Against Indirect Prompt Injection Attacks With Spotlighting | D8: Hines | E8: Keegan Hines, Gary Lopez, Matthew Hall, Federico Zarfati, Yonatan Zunger, Emre Kıcıman | F8: 2024 | G8: CAMLIS '24 (Conference on Applied ML for Information Security), Arlington VA; CEUR workshop proceedings | H8: not printed on this copy | I8: Peer-reviewed workshop | J8: hines_et_al_2024_defending_against_indirect_prompt_injection_with_spotlighting.pdf | L8: Defense | M8: Tool output (indirect, at runtime) | N8: Attacker embeds instructions in external documents (e.g., websites) the LLM processes alongside user commands; user is an unaware bystander | O8: Black-box; attacker controls the content of an untrusted document; defense operates only through the system prompt (Sec. 1) | P8: Task hijack (unauthorised action) | Q8: Instruction injection | R8: Input transformation / prompting | S8: Prompt / input layer | T8: System prompt and user command trusted; every external input block is marked or transformed so the model can tell provenance | U8: Own synthetic corpus of 1,000 documents containing injections; NLP task benchmarks for utility (Sec. 4) | V8: ASR (attack success rate) | W8: Reduces ASR from >50% to <2% on GPT-family models with minimal task impact (abstract) | X8: No | Y8: Medium | Z8: Fits frame | AA8: Claude (draft; verify) | AB8: 2026-09-12 | AC8: Three instantiations: delimiting, datamarking, encoding. Cheap baseline defense; AgentDojo includes a variant.
A9: P08 | B9: PromptShield | C9: PromptShield: Deployable Detection for Prompt Injection Attacks | D9: Jacob | E9: Dennis Jacob, Hend Alzahrani, Zhanhao Hu, Basel Alomair, David Wagner | F9: 2025 | G9: not printed on this copy | H9: arXiv:2501.15145v2 [cs.CR], 12 Apr 2025 | I9: Preprint (as downloaded) | J9: jacob_et_al_promptshield_deployable_detection_for_prompt_injection.pdf | L9: Mixed (note which) | M9: Multiple (note which) | N9: Adversary controls part of the data an LLM-integrated application processes (application-structured data); conversational chatbot data assumed injection-free | O9: Black-box; deployment framing with the base-rate problem: benign traffic dominates, so the detector must run at very low FPR (Sec. 1) | P9: Task hijack (unauthorised action) | Q9: Instruction injection | R9: Detection (classifier / probe) | S9: Prompt / input layer | T9: Conversational data treated as trusted (a user is unlikely to attack themselves); application-structured data untrusted | U9: PromptShield benchmark (own curation of conversational and application-structured data) | V9: FPR / FNR / TPR | W9: Detector reaches 65.3% TPR at 0.1% FPR vs 9.4% for the best prior scheme (Sec. 1 and Fig. 2) | X9: No | Y9: High | Z9: Fits frame | AA9: Claude (draft; verify) | AB9: 2026-09-12 | AC9: Mixed = benchmark + fine-tuned detector. The low-FPR evaluation regime is the one our detector work should adopt. Distinguishes prompt injection from jailbreaks.
A10: P09 | B10: Liu (formalizing PI) | C10: Formalizing and Benchmarking Prompt Injection Attacks and Defenses | D10: Liu | E10: Yupei Liu, Yuqi Jia, Runpeng Geng, Jinyuan Jia, Neil Zhenqiang Gong | F10: UNVERIFIED | G10: UNVERIFIED: no venue, year, or arXiv stamp on this copy | H10: not printed on this copy | I10: UNVERIFIED | J10: liu_et_al_formalizing_and_benchmarking_prompt_injection_attacks_defenses.pdf | L10: Mixed (note which) | M10: Multiple (note which) | N10: Attacker controls the data an LLM-integrated application processes (e.g., a resume, a web page); the instruction prompt is the application's | O10: Formalizes attacker goal, background knowledge, and capabilities: attacker crafts compromised data to make the app perform an injected task; backend LLM integrity assumed; see Sec. 3 for the exact knowledge assumptions | P10: Task hijack (unauthorised action) | Q10: Instruction injection | R10: N/A (attack- or benchmark-only) | S10: N/A | T10: Instruction prompt trusted, data untrusted; existing attacks are special cases of the framework | U10: Open-Prompt-Injection: 5 attacks, 10 defenses, 10 LLMs, 7 tasks (abstract) | V10: ASR (attack success rate) | W10: Combined Attack (framework-derived) is the most effective attack (Sec. 6, Table 6b); no evaluated defense is sufficient (Sec. 1). Paper's metric is named attack success score (ASS) | X10: No | Y10: High | Z10: Fits frame | AA10: Claude (draft; verify) | AB10: 2026-09-12 | AC10: Mixed = formal framework + benchmark + new attack. Second taxonomy paper for the frame. Evaluates prevention and detection defenses incl. known-answer detection. Venue/year UNVERIFIED on this copy.
A11: P10 | B11: Jatmo | C11: Jatmo: Prompt Injection Defense by Task-Specific Finetuning | D11: Piet | E11: Julien Piet, Maha Alrashed, Chawin Sitawarin, Sizhe Chen, Zeming Wei, Elizabeth Sun, Basel Alomair, David Wagner | F11: 2024 | G11: not printed on this copy | H11: arXiv:2312.17673v2 [cs.CR], 8 Jan 2024 | I11: Preprint (as downloaded) | J11: piet_at_al_2026_jatmo_2024_prompt_injection_defense_task_specific_finetuning.pdf | L11: Defense | M11: Multiple (note which) | N11: Attacker has full control of the input data to a single-task LLM application | O11: Attacker assumed to have full control of the input data (Sec. 3, 'Threat model'); black-box w.r.t. the fine-tuned model | P11: Task hijack (unauthorised action) | Q11: Instruction injection | R11: Training-time (fine-tune / alignment) | S11: Model weights | T11: Task prompt fixed by the developer; model is a non-instruction-tuned base fine-tuned on teacher outputs so it cannot follow instructions in data | U11: Seven tasks with teacher-generated datasets (abstract) | V11: ASR (attack success rate) | W11: Best attacks succeed in <0.5% of cases vs 87% against GPT-3.5-Turbo (abstract) | X11: No | Y11: Low | Z11: Fits frame | AA11: Claude (draft; verify) | AB11: 2026-09-12 | AC11: Single-task models only; not applicable to general-purpose agents. Useful as the 'remove instruction-following' end of the defense spectrum.
A12: P11 | B12: RevPRAG | C12: RevPRAG: Revealing Poisoning Attacks in Retrieval-Augmented Generation through LLM Activation Analysis | D12: Tan | E12: Xue Tan, Hao Luan, Mingyu Luo, Xiaoyan Sun, Ping Chen, Jun Dai | F12: 2025 | G12: Findings of ACL: EMNLP 2025, pp. 12999–13011 | H12: not printed on this copy | I12: Peer-reviewed conference (Findings) | J12: tan_et_al_2025_revprag_revealing_of_poisoning_attacks_in_retrieval_augmented_generation_through_LLM_activation_analysis.pdf | L12: Defense | M12: RAG corpus / retriever | N12: Attacker injects poisoned texts into the public knowledge database a RAG system retrieves from | O12: Attacker injects m poisoned texts per target question; no knowledge of the LLM; white-box access to the retriever (Sec. 3.1) | P12: Misinformation / wrong answer | Q12: Content poisoning | R12: Detection (classifier / probe) | S12: Orchestrator / runtime | T12: LLM's own activations are trusted as a signal; a probe over hidden states separates poisoned from correct responses; no weight change | U12: Natural Questions, HotpotQA, MS-MARCO; multiple RAG architectures (Sec. 5) | V12: FPR / FNR / TPR | W12: 98% true positive rate with false positive rate close to 1% (abstract) | X12: No | Y12: High | Z12: Fits frame | AA12: Claude (draft; verify) | AB12: 2026-09-12 | AC12: Activation-probe detection on the RAG surface; natural comparison point for a probe on the tool/MCP surface. Enforcement coded as runtime because the probe wraps inference rather than changing weights.
A13: P12 | B13: MCPTox | C13: MCPTox: A Benchmark for Tool Poisoning Attack on Real-World MCP Servers | D13: Wang | E13: Zhiqiang Wang, Yichao Gao, Yanting Wang, Suyuan Liu, Haifeng Sun, Haoran Cheng, Guanquan Shi, Haohua Du, Xiangyang Li | F13: 2025 | G13: not printed on this copy | H13: arXiv:2508.14925v1 [cs.CR], 19 Aug 2025 | I13: Preprint (as downloaded) | J13: wang_et_al_mcptox_a_benchmark_for_tool_poisoning_attack.pdf | L13: Benchmark / environment | M13: Tool description / metadata (MCP) | N13: Malicious MCP server author embeds instructions in a tool's description; payload enters the agent's context at registration, before any tool executes | O13: Attacker controls tool metadata only; no execution needed; three attack templates over 45 live servers and 353 real tools (abstract) | P13: Task hijack (unauthorised action) | Q13: Instruction injection | R13: N/A (attack- or benchmark-only) | S13: N/A | T13: Agents treat registered tool descriptions as trusted instructions | U13: MCPTox: 1,312 test cases, 10 risk categories, 20 LLM agents (abstract) | V13: ASR (attack success rate) | W13: o1-mini ASR 72.8%; highest refusal rate (Claude-3.7-Sonnet) under 3%; more capable models often more susceptible (abstract) | X13: Yes | Y13: High | Z13: Fits frame | AA13: Claude (draft; verify) | AB13: 2026-09-12 | AC13: Tool poisoning at registration time is a distinct surface from tool-output injection at runtime; keep the two separate in the frame. Repository link is anonymized (AAAI26 submission), so a published version may exist.
... A21: P20 | B21: PoisonedRAG | C21: PoisonedRAG: Knowledge Corruption Attacks to Retrieval-Augmented Generation of Large Language Models | D21: Zou | E21: Wei Zou, Runpeng Geng, Binghui Wang, Jinyuan Jia | F21: 2024 | G21: not printed on this copy | H21: arXiv:2402.07867v3 [cs.CR], 13 Aug 2024 | I21: Preprint (as downloaded) | J21: zou_et_al_2025_poisoned_rag_knowledge_corruption_attacks_to_retrieval_augmented_generation_of_LLMs.pdf | L21: Attack | M21: RAG corpus / retriever | N21: Attacker injects a few malicious texts into the knowledge database of a RAG system | O21: Attacker picks target questions and target answers; black-box and white-box variants depending on knowledge of the retriever (Sec. 3, 'Threat Model') | P21: Misinformation / wrong answer | Q21: Content poisoning | R21: N/A (attack- or benchmark-only) | S21: N/A | T21: Knowledge database treated as trusted ground for generation | U21: Natural Questions, HotpotQA, MS-MARCO; 8 LLMs; several defenses evaluated (Sec. 5) | V21: ASR (attack success rate) | W21: 90% ASR when injecting five malicious texts per target question into a database of millions of texts (abstract) | X21: No | Y21: Medium | Z21: Fits frame | AA21: Claude (draft; verify) | AB21: 2026-09-12 | AC21: Canonical RAG poisoning attack; the attack most RAG defenses in this set evaluate against. Downloaded copy is the arXiv v3; a peer-reviewed version may exist, verify.

Sheet Coverage
A1: Coverage of the coded papers across each dimension
A2: Counts update automatically as rows on 'Coding Matrix' are coded. Counts use rows 2 to 200 so appended papers are included.
A4: Papers coded so far (Paper type filled) | B4: =COUNTA('Coding Matrix'!L2:L200)
A5: Papers in matrix | B5: =COUNTA('Coding Matrix'!A2:A200)
A7: Paper type | B7: Count | C7: Share of coded
A8: Attack | B8: =COUNTIF('Coding Matrix'!L$2:L$200,A8) | C8: =IF($B$4=0,0,B8/$B$4)
A9: Defense | B9: =COUNTIF('Coding Matrix'!L$2:L$200,A9) | C9: =IF($B$4=0,0,B9/$B$4)
A10: Benchmark / environment | B10: =COUNTIF('Coding Matrix'!L$2:L$200,A10) | C10: =IF($B$4=0,0,B10/$B$4)
A11: Evaluation methodology | B11: =COUNTIF('Coding Matrix'!L$2:L$200,A11) | C11: =IF($B$4=0,0,B11/$B$4)
A12: Survey / taxonomy | B12: =COUNTIF('Coding Matrix'!L$2:L$200,A12) | C12: =IF($B$4=0,0,B12/$B$4)
A13: Mixed (note which) | B13: =COUNTIF('Coding Matrix'!L$2:L$200,A13) | C13: =IF($B$4=0,0,B13/$B$4)
A15: Attack surface | B15: Count | C15: Share of coded
A16: RAG corpus / retriever | B16: =COUNTIF('Coding Matrix'!M$2:M$200,A16) | C16: =IF($B$4=0,0,B16/$B$4)
A17: Tool output (indirect, at runtime) | B17: =COUNTIF('Coding Matrix'!M$2:M$200,A17) | C17: =IF($B$4=0,0,B17/$B$4)
A18: Tool description / metadata (MCP) | B18: =COUNTIF('Coding Matrix'!M$2:M$200,A18) | C18: =IF($B$4=0,0,B18/$B$4)
A19: Direct user input | B19: =COUNTIF('Coding Matrix'!M$2:M$200,A19) | C19: =IF($B$4=0,0,B19/$B$4)
A20: Multiple (note which) | B20: =COUNTIF('Coding Matrix'!M$2:M$200,A20) | C20: =IF($B$4=0,0,B20/$B$4)
A22: Attack objective | B22: Count | C22: Share of coded
A23: Task hijack (unauthorised action) | B23: =COUNTIF('Coding Matrix'!P$2:P$200,A23) | C23: =IF($B$4=0,0,B23/$B$4)
A24: Data exfiltration | B24: =COUNTIF('Coding Matrix'!P$2:P$200,A24) | C24: =IF($B$4=0,0,B24/$B$4)
A25: Misinformation / wrong answer | B25: =COUNTIF('Coding Matrix'!P$2:P$200,A25) | C25: =IF($B$4=0,0,B25/$B$4)
A26: Denial of service | B26: =COUNTIF('Coding Matrix'!P$2:P$200,A26) | C26: =IF($B$4=0,0,B26/$B$4)
A27: Tool-selection manipulation | B27: =COUNTIF('Coding Matrix'!P$2:P$200,A27) | C27: =IF($B$4=0,0,B27/$B$4)
A28: Multiple (note which) | B28: =COUNTIF('Coding Matrix'!P$2:P$200,A28) | C28: =IF($B$4=0,0,B28/$B$4)
A29: N/A (defense-only) | B29: =COUNTIF('Coding Matrix'!P$2:P$200,A29) | C29: =IF($B$4=0,0,B29/$B$4)
A31: Defense class | B31: Count | C31: Share of coded
A32: Detection (classifier / probe) | B32: =COUNTIF('Coding Matrix'!R$2:R$200,A32) | C32: =IF($B$4=0,0,B32/$B$4)
A33: Input transformation / prompting | B33: =COUNTIF('Coding Matrix'!R$2:R$200,A33) | C33: =IF($B$4=0,0,B33/$B$4)
A34: Training-time (fine-tune / alignment) | B34: =COUNTIF('Coding Matrix'!R$2:R$200,A34) | C34: =IF($B$4=0,0,B34/$B$4)
A35: Architectural isolation | B35: =COUNTIF('Coding Matrix'!R$2:R$200,A35) | C35: =IF($B$4=0,0,B35/$B$4)
A36: Runtime policy / capability enforcement | B36: =COUNTIF('Coding Matrix'!R$2:R$200,A36) | C36: =IF($B$4=0,0,B36/$B$4)
A37: Certified / provable | B37: =COUNTIF('Coding Matrix'!R$2:R$200,A37) | C37: =IF($B$4=0,0,B37/$B$4)
A38: Forensics / traceback | B38: =COUNTIF('Coding Matrix'!R$2:R$200,A38) | C38: =IF($B$4=0,0,B38/$B$4)
A39: N/A (attack- or benchmark-only) | B39: =COUNTIF('Coding Matrix'!R$2:R$200,A39) | C39: =IF($B$4=0,0,B39/$B$4)
A41: Enforcement point | B41: Count | C41: Share of coded
A42: Model weights | B42: =COUNTIF('Coding Matrix'!S$2:S$200,A42) | C42: =IF($B$4=0,0,B42/$B$4)
A43: Prompt / input layer | B43: =COUNTIF('Coding Matrix'!S$2:S$200,A43) | C43: =IF($B$4=0,0,B43/$B$4)
A44: Orchestrator / runtime | B44: =COUNTIF('Coding Matrix'!S$2:S$200,A44) | C44: =IF($B$4=0,0,B44/$B$4)
A45: Tool layer / MCP server | B45: =COUNTIF('Coding Matrix'!S$2:S$200,A45) | C45: =IF($B$4=0,0,B45/$B$4)
A46: Retriever / index | B46: =COUNTIF('Coding Matrix'!S$2:S$200,A46) | C46: =IF($B$4=0,0,B46/$B$4)
...
